2024-02-16 11:15:09 | ERROR | 'id_user'
2024-02-16 11:15:09 | ERROR | Traceback (most recent call last):
  File "C:\Users\bloos\OneDrive\Documentos\Programacion\Proyectos\BPPFP\src\routes\HomeRoutes.py", line 36, in get_follower
    get_followers = Follow.get_followers(connection, session['id_user'])
                                                     ~~~~~~~^^^^^^^^^^^
  File "C:\Users\bloos\OneDrive\Documentos\Programacion\Proyectos\BPPFP\venv\Lib\site-packages\flask\sessions.py", line 79, in __getitem__
    return super().__getitem__(key)
           ^^^^^^^^^^^^^^^^^^^^^^^^
KeyError: 'id_user'

2024-02-16 11:15:10 | ERROR | 'id_user'
2024-02-16 11:15:10 | ERROR | Traceback (most recent call last):
  File "C:\Users\bloos\OneDrive\Documentos\Programacion\Proyectos\BPPFP\src\routes\HomeRoutes.py", line 54, in get_suggest_follwer
    get_suggest_follwers = Follow.suggest_followers(connection, session['id_user'])
                                                                ~~~~~~~^^^^^^^^^^^
  File "C:\Users\bloos\OneDrive\Documentos\Programacion\Proyectos\BPPFP\venv\Lib\site-packages\flask\sessions.py", line 79, in __getitem__
    return super().__getitem__(key)
           ^^^^^^^^^^^^^^^^^^^^^^^^
KeyError: 'id_user'

2024-02-16 11:28:45 | ERROR | connection already closed
2024-02-16 11:28:45 | ERROR | Traceback (most recent call last):
  File "C:\Users\bloos\OneDrive\Documentos\Programacion\Proyectos\BPPFP\src\models\FollowModel.py", line 17, in follow
    cursor = connection.cursor()
             ^^^^^^^^^^^^^^^^^^^
psycopg2.InterfaceError: connection already closed

2024-02-16 11:28:45 | ERROR | cannot access local variable 'cursor' where it is not associated with a value
2024-02-16 11:28:45 | ERROR | Traceback (most recent call last):
  File "C:\Users\bloos\OneDrive\Documentos\Programacion\Proyectos\BPPFP\src\routes\FollowRoutes.py", line 28, in follow
    follow.follow(connection)
  File "C:\Users\bloos\OneDrive\Documentos\Programacion\Proyectos\BPPFP\src\models\FollowModel.py", line 30, in follow
    cursor.close()
    ^^^^^^
UnboundLocalError: cannot access local variable 'cursor' where it is not associated with a value

2024-02-16 11:29:05 | ERROR | connection already closed
2024-02-16 11:29:05 | ERROR | Traceback (most recent call last):
  File "C:\Users\bloos\OneDrive\Documentos\Programacion\Proyectos\BPPFP\src\models\FollowModel.py", line 17, in follow
    cursor = connection.cursor()
             ^^^^^^^^^^^^^^^^^^^
psycopg2.InterfaceError: connection already closed

2024-02-16 11:29:05 | ERROR | cannot access local variable 'cursor' where it is not associated with a value
2024-02-16 11:29:05 | ERROR | Traceback (most recent call last):
  File "C:\Users\bloos\OneDrive\Documentos\Programacion\Proyectos\BPPFP\src\routes\FollowRoutes.py", line 28, in follow
    follow.follow(connection)
  File "C:\Users\bloos\OneDrive\Documentos\Programacion\Proyectos\BPPFP\src\models\FollowModel.py", line 30, in follow
    cursor.close()
    ^^^^^^
UnboundLocalError: cannot access local variable 'cursor' where it is not associated with a value

2024-02-16 11:36:46 | ERROR | '>' not supported between instances of 'tuple' and 'int'
2024-02-16 11:36:46 | ERROR | Traceback (most recent call last):
  File "C:\Users\bloos\OneDrive\Documentos\Programacion\Proyectos\BPPFP\src\models\FollowModel.py", line 140, in check_verefy_following
    if check_result and check_result > 0:
                        ^^^^^^^^^^^^^^^^
TypeError: '>' not supported between instances of 'tuple' and 'int'

2024-02-16 11:36:59 | ERROR | '>' not supported between instances of 'tuple' and 'int'
2024-02-16 11:36:59 | ERROR | Traceback (most recent call last):
  File "C:\Users\bloos\OneDrive\Documentos\Programacion\Proyectos\BPPFP\src\models\FollowModel.py", line 140, in check_verefy_following
    if check_result and check_result > 0:
                        ^^^^^^^^^^^^^^^^
TypeError: '>' not supported between instances of 'tuple' and 'int'

